Workbook

Sheet Site List
A2: REQUEST FOR PROPOSAL - THE EDEN PARK TRUST
A4: Postal Address: | B4: Private Bag 56906, Mount Eden, Auckland 1446
A6: TIME OF USE CONNECTIONS:
A8: ICP Number: | B8: Physical Address: | C8: GXP: | D8: Commencement: | E8: Load Group: | F8: Loss Factor: | G8: Capacity: | H8: Demand: | I8: Meter Owner: | J8: Category: | K8: Installation Type: | L8: Current Supplier: | M8: Est. Usage:
A9: 0132426315LC55E | B9: 2 A Reimers Avenue, Morningside, Auckland | C9: ROS1101 | D9: 46054 | E9: AHVT | F9: VECA3 | G9: 650 | I9: AMCI | J9: 4 | K9: L | L9: Mercury | M9: ='48 Part'!B16 -> 1403702.5
A10: 0138572097LCAAE | B10: Walters Road, Kingsland, Auckland | C10: ROS1101 | D10: 46054 | E10: ATXT | F10: VECA3 | G10: 750 | I10: AMCI | J10: 4 | K10: L | L10: Mercury | M10: ='48 Part'!B42 -> 1294789.2
A11: 0157195775LCCFD | B11: Walters Road, Kingsland, Auckland | C11: ROS1101 | D11: 46054 | E11: ATXT | F11: VECA3 | G11: 1500 | I11: AMCI | J11: 3 | K11: L | L11: Mercury | M11: ='48 Part'!B68 -> 1695359.4
A12: 1001153957LC737 | B12: 4-42 Reimers Avenue, Mount Eden, Auckland | C12: ROS1101 | D12: 46054 | E12: ATXT | F12: VECA3 | G12: 1000 | I12: AMCI | J12: 4 | K12: L | L12: Mercury | M12: ='48 Part'!B94 -> 2283477.7
A14: NON TIME OF USE CONNECTIONS: | L14: TOU Total | M14: =SUM(M9:M12) -> 6677328.8 | N14: kWh/annum
A16: ICP Number: | B16: Physical Address: | C16: GXP: | D16: Commencement: | E16: Load Group: | F16: Loss Factor: | G16: Capacity: | H16: Demand: | I16: Meter Owner: | J16: Category: | K16: Installation Type: | L16: Current Supplier: | M16: Est. Usage:
A17: 0157211029LCDF8 | B17: 86 Sandringham Road, Morningside, Auckland | C17: ROS1101 | D17: 46054 | E17: ABSH | F17: VECA1 | G17: 41 | H17: 41 | I17: NGCM | J17: 1 | K17: L | L17: Contact Energy | M17: 19796
A18: 1001140332LC583 | B18: Reimers Avenue, Morningside, Auckland | C18: ROS1101 | D18: 46054 | E18: ABSH | F18: VECA1 | G18: 41 | H18: 41 | I18: NGCM | J18: 1 | K18: L | L18: Contact Energy | M18: 70757
L20: NTOU Total | M20: =SUM(M17:M18) -> 90553 | N20: kWh/annum
L22: TOTAL ELECTRICITY | M22: =M20+M14 -> 6767881.8 | N22: kWh/annum
A23: NON TIME OF USE GAS CONNECTIONS:
A25: ICP Number: | B25: Physical Address: | C25: Gas gate: | D25: Commencement: | E25: Price cat: | F25: Meter cat: | L25: Current Supplier: | M25: Est. Usage:
A26: 0000161061QTA32 | B26: 58 Walters Road Kingsland Auckland | C26: WKM17701 | D26: 45931 | E26: GA03 | F26: M11BR14H | L26: Nova Energy | M26: 275782.91
A27: 1001154923QTDE1 | B27: 2A Reimers Avenue Morningside Auckland | C27: WKM17701 | D27: 45931 | E27: GA04 | F27: M11BR30H | L27: Nova Energy | M27: 953762.75
L29: TOTAL NATURAL GAS | M29: =SUM(M26:M27) -> 1229545.7 | N29: kWh/annum
A30: All totals are estimates based on historical information | M30: =M29/277.78 -> 4426.329 | N30: GJ/annum
A31: No liability is accepted for any error or omission

Sheet 48 Part
A2: ='Site List'!A2:M2 -> REQUEST FOR PROPOSAL - THE EDEN PARK TRUST
A5: Postal address: | B5: ='Site List'!B4 -> Private Bag 56906, Mount Eden, Auckland 1446
A7: Physical address: | B7: =VLOOKUP(B8,'Site List'!$A$9:$M$21,2,FALSE) -> 2 A Reimers Avenue, Morningside, Auckland
A8: ICP Number: | B8: ='Site List'!A9 -> 0132426315LC55E
A9: GXP: | B9: =VLOOKUP(B8,'Site List'!$A$9:$M$21,3,FALSE) -> ROS1101
A10: Commencement: | B10: =VLOOKUP(B8,'Site List'!$A$9:$M$21,4,FALSE) -> 46054
A11: Load Group: | B11: =VLOOKUP(B8,'Site List'!$A$9:$M$21,5,FALSE) -> AHVT | C11: Demand: | D11: =VLOOKUP(B8,'Site List'!$A$9:$M$21,8,FALSE)
A12: Loss Factor: | B12: =VLOOKUP(B8,'Site List'!$A$9:$M$21,6,FALSE) -> VECA3 | C12: Capacity: | D12: =VLOOKUP(B8,'Site List'!$A$9:$M$21,7,FALSE) -> 650
A13: Meter owner: | B13: =VLOOKUP(B8,'Site List'!$A$9:$M$21,9,FALSE) -> AMCI | C13: Cat: | D13: =VLOOKUP(B8,'Site List'!$A$9:$M$21,10,FALSE) -> 4
A14: Installation type: | B14: =VLOOKUP(B8,'Site List'!$A$9:$M$21,11,FALSE) -> L
A15: Current supplier: | B15: =VLOOKUP(B8,'Site List'!$A$9:$M$21,12,FALSE) -> Mercury
A16: Est. Usage: | B16: =SUM(B20:E31) -> 1403702.5 | C16: kWh/annum
A18: kWh | B18: Business Day | D18: Non Business day
B19: 0000-0800 | C19: 0800-2400 | D19: 0000-0800 | E19: 0800-2400
A20: =B10 -> 46054 | B20: =SUM('144 Part'!B20:C20) -> 20820.48 | C20: =SUM('144 Part'!D20:G20) -> 51114.88 | D20: =SUM('144 Part'!H20:I20) -> 8285.24 | E20: =SUM('144 Part'!J20:M20) -> 20609.16
A21: =DATE(YEAR(A20),MONTH(A20)+1,DAY(A20)) -> 46082 | B21: =SUM('144 Part'!B21:C21) -> 23047.12 | C21: =SUM('144 Part'!D21:G21) -> 62829.37 | D21: =SUM('144 Part'!H21:I21) -> 11461.88 | E21: =SUM('144 Part'!J21:M21) -> 25105.32
A22: =DATE(YEAR(A21),MONTH(A21)+1,DAY(A21)) -> 46113 | B22: =SUM('144 Part'!B22:C22) -> 24177 | C22: =SUM('144 Part'!D22:G22) -> 56895.92 | D22: =SUM('144 Part'!H22:I22) -> 9279.52 | E22: =SUM('144 Part'!J22:M22) -> 24257.72
A23: =DATE(YEAR(A22),MONTH(A22)+1,DAY(A22)) -> 46143 | B23: =SUM('144 Part'!B23:C23) -> 26464.28 | C23: =SUM('144 Part'!D23:G23) -> 67966.16 | D23: =SUM('144 Part'!H23:I23) -> 10989.36 | E23: =SUM('144 Part'!J23:M23) -> 26336.8
A24: =DATE(YEAR(A23),MONTH(A23)+1,DAY(A23)) -> 46174 | B24: =SUM('144 Part'!B24:C24) -> 24740.04 | C24: =SUM('144 Part'!D24:G24) -> 62786.48 | D24: =SUM('144 Part'!H24:I24) -> 10196.12 | E24: =SUM('144 Part'!J24:M24) -> 22749.96
A25: =DATE(YEAR(A24),MONTH(A24)+1,DAY(A24)) -> 46204 | B25: =SUM('144 Part'!B25:C25) -> 31608.4 | C25: =SUM('144 Part'!D25:G25) -> 74988.08 | D25: =SUM('144 Part'!H25:I25) -> 11161.52 | E25: =SUM('144 Part'!J25:M25) -> 27044.4
A26: =DATE(YEAR(A25),MONTH(A25)+1,DAY(A25)) -> 46235 | B26: =SUM('144 Part'!B26:C26) -> 21774.96 | C26: =SUM('144 Part'!D26:G26) -> 54903.4 | D26: =SUM('144 Part'!H26:I26) -> 9894.36 | E26: =SUM('144 Part'!J26:M26) -> 23878
A27: =DATE(YEAR(A26),MONTH(A26)+1,DAY(A26)) -> 46266 | B27: =SUM('144 Part'!B27:C27) -> 22169.76 | C27: =SUM('144 Part'!D27:G27) -> 53140.16 | D27: =SUM('144 Part'!H27:I27) -> 8792.56 | E27: =SUM('144 Part'!J27:M27) -> 21007.08
A28: =DATE(YEAR(A27),MONTH(A27)+1,DAY(A27)) -> 46296 | B28: =SUM('144 Part'!B28:C28) -> 26396.64 | C28: =SUM('144 Part'!D28:G28) -> 63609.08 | D28: =SUM('144 Part'!H28:I28) -> 8735 | E28: =SUM('144 Part'!J28:M28) -> 19109.8
A29: =DATE(YEAR(A28),MONTH(A28)+1,DAY(A28)) -> 46327 | B29: =SUM('144 Part'!B29:C29) -> 24186 | C29: =SUM('144 Part'!D29:G29) -> 59282.4 | D29: =SUM('144 Part'!H29:I29) -> 10762.08 | E29: =SUM('144 Part'!J29:M29) -> 24003.2
A30: =DATE(YEAR(A29),MONTH(A29)+1,DAY(A29)) -> 46357 | B30: =SUM('144 Part'!B30:C30) -> 21875.56 | C30: =SUM('144 Part'!D30:G30) -> 51286.32 | D30: =SUM('144 Part'!H30:I30) -> 8727.72 | E30: =SUM('144 Part'!J30:M30) -> 19273.6
A31: =DATE(YEAR(A30),MONTH(A30)+1,DAY(A30)) -> 46388 | B31: =SUM('144 Part'!B31:C31) -> 23852.12 | C31: =SUM('144 Part'!D31:G31) -> 60391.24 | D31: =SUM('144 Part'!H31:I31) -> 9255.96 | E31: =SUM('144 Part'!J31:M31) -> 22480.28
A33: Physical address: | B33: =VLOOKUP(B34,'Site List'!$A$9:$M$21,2,FALSE) -> Walters Road, Kingsland, Auckland
A34: ICP Number: | B34: ='Site List'!A10 -> 0138572097LCAAE
A35: GXP: | B35: =VLOOKUP(B34,'Site List'!$A$9:$M$21,3,FALSE) -> ROS1101
A36: Commencement: | B36: =VLOOKUP(B34,'Site List'!$A$9:$M$21,4,FALSE) -> 46054
A37: Load Group: | B37: =VLOOKUP(B34,'Site List'!$A$9:$M$21,5,FALSE) -> ATXT | C37: Demand: | D37: =VLOOKUP(B34,'Site List'!$A$9:$M$21,8,FALSE)
A38: Loss Factor: | B38: =VLOOKUP(B34,'Site List'!$A$9:$M$21,6,FALSE) -> VECA3 | C38: Capacity: | D38: =VLOOKUP(B34,'Site List'!$A$9:$M$21,7,FALSE) -> 750
A39: Meter owner: | B39: =VLOOKUP(B34,'Site List'!$A$9:$M$21,9,FALSE) -> AMCI | C39: Cat: | D39: =VLOOKUP(B34,'Site List'!$A$9:$M$21,10,FALSE) -> 4
A40: Installation type: | B40: =VLOOKUP(B34,'Site List'!$A$9:$M$21,11,FALSE) -> L
A41: Current supplier: | B41: =VLOOKUP(B34,'Site List'!$A$9:$M$21,12,FALSE) -> Mercury
A42: Est. Usage: | B42: =SUM(B46:E57) -> 1294789.2 | C42: kWh/annum
A44: kWh | B44: Business Day | D44: Non Business day
B45: 0000-0800 | C45: 0800-2400 | D45: 0000-0800 | E45: 0800-2400
A46: =B36 -> 46054 | B46: =SUM('144 Part'!B46:C46) -> 17292.16 | C46: =SUM('144 Part'!D46:G46) -> 49905.088 | D46: =SUM('144 Part'!H46:I46) -> 6957.792 | E46: =SUM('144 Part'!J46:M46) -> 19050.464
A47: =DATE(YEAR(A46),MONTH(A46)+1,DAY(A46)) -> 46082 | B47: =SUM('144 Part'!B47:C47) -> 18488.032 | C47: =SUM('144 Part'!D47:G47) -> 57052.64 | D47: =SUM('144 Part'!H47:I47) -> 10182.912 | E47: =SUM('144 Part'!J47:M47) -> 24371.392
...

Sheet 144 Part
A2: ='48 Part'!A2:N3 -> REQUEST FOR PROPOSAL - THE EDEN PARK TRUST
A5: Postal address: | B5: ='48 Part'!B5 -> Private Bag 56906, Mount Eden, Auckland 1446
A7: Physical address: | B7: ='48 Part'!B7 -> 2 A Reimers Avenue, Morningside, Auckland
A8: ICP Number: | B8: ='48 Part'!B8 -> 0132426315LC55E
A9: GXP: | B9: ='48 Part'!B9 -> ROS1101
A10: Commencement: | B10: ='48 Part'!B10 -> 46054
A11: Load Group: | B11: ='48 Part'!B11 -> AHVT | C11: Demand: | D11: ='48 Part'!D11
A12: Loss Factor: | B12: ='48 Part'!B12 -> VECA3 | C12: Capacity: | D12: ='48 Part'!D12 -> 650
A13: Meter owner: | B13: ='48 Part'!B13 -> AMCI | C13: Cat: | D13: ='48 Part'!D13 -> 4
A14: Installation type: | B14: ='48 Part'!B14 -> L
A15: Current supplier: | B15: ='48 Part'!B15 -> Mercury
A16: Est. Usage: | B16: =SUM(B20:M31) -> 1403702.5 | C16: kWh/annum
A18: kWh | B18: Business Day | H18: Non Business Day
B19: 0000-0400 | C19: 0400-0800 | D19: 0800-1200 | E19: 1200-1600 | F19: 1600-2000 | G19: 2000-2400 | H19: 0000-0400 | I19: 0400-0800 | J19: 0800-1200 | K19: 1200-1600 | L19: 1600-2000 | M19: 2000-2400
A20: =B10 -> 46054 | B20: 9911.8 | C20: 10908.68 | D20: 13577.92 | E20: 14287.24 | F20: 12245.12 | G20: 11004.6 | H20: 4066.64 | I20: 4218.6 | J20: 4628.2 | K20: 5346.24 | L20: 5697.44 | M20: 4937.28
A21: =DATE(YEAR(A20),MONTH(A20)+1,DAY(A20)) -> 46082 | B21: 10960.52 | C21: 12086.6 | D21: 16233.17 | E21: 16151.32 | F21: 16125.2 | G21: 14319.68 | H21: 5795.24 | I21: 5666.64 | J21: 5931 | K21: 6232 | L21: 6778.92 | M21: 6163.4
A22: =DATE(YEAR(A21),MONTH(A21)+1,DAY(A21)) -> 46113 | B22: 11177.64 | C22: 12999.36 | D22: 15592.08 | E22: 15082.32 | F22: 13851.68 | G22: 12369.84 | H22: 4557.64 | I22: 4721.88 | J22: 5341.6 | K22: 6164 | L22: 6967.32 | M22: 5784.8
A23: =DATE(YEAR(A22),MONTH(A22)+1,DAY(A22)) -> 46143 | B23: 11722.84 | C23: 14741.44 | D23: 18550.48 | E23: 17546.88 | F23: 17414.52 | G23: 14454.28 | H23: 5043.68 | I23: 5945.68 | J23: 6521.24 | K23: 6795.52 | L23: 7042.12 | M23: 5977.92
A24: =DATE(YEAR(A23),MONTH(A23)+1,DAY(A23)) -> 46174 | B24: 10713.2 | C24: 14026.84 | D24: 17330.76 | E24: 16521.76 | F24: 15876.6 | G24: 13057.36 | H24: 4596.04 | I24: 5600.08 | J24: 5862.48 | K24: 5778.56 | L24: 5830.48 | M24: 5278.44
A25: =DATE(YEAR(A24),MONTH(A24)+1,DAY(A24)) -> 46204 | B25: 14253.96 | C25: 17354.44 | D25: 20503.64 | E25: 19686.08 | F25: 18451.44 | G25: 16346.92 | H25: 5253.28 | I25: 5908.24 | J25: 6587.08 | K25: 6965.96 | L25: 7149.24 | M25: 6342.12
A26: =DATE(YEAR(A25),MONTH(A25)+1,DAY(A25)) -> 46235 | B26: 9672.84 | C26: 12102.12 | D26: 14817.28 | E26: 14413.2 | F26: 13829.2 | G26: 11843.72 | H26: 4708.12 | I26: 5186.24 | J26: 5654.04 | K26: 5846.88 | L26: 6716.48 | M26: 5660.6
A27: =DATE(YEAR(A26),MONTH(A26)+1,DAY(A26)) -> 46266 | B27: 10489.6 | C27: 11680.16 | D27: 14335.44 | E27: 13774.12 | F27: 13210.08 | G27: 11820.52 | H27: 4151.12 | I27: 4641.44 | J27: 5189.68 | K27: 5362.44 | L27: 5408.88 | M27: 5046.08
A28: =DATE(YEAR(A27),MONTH(A27)+1,DAY(A27)) -> 46296 | B28: 12448.96 | C28: 13947.68 | D28: 17201.08 | E28: 16859.08 | F28: 15503.96 | G28: 14044.96 | H28: 4209.12 | I28: 4525.88 | J28: 4799.12 | K28: 5050.56 | L28: 4720.48 | M28: 4539.64
A29: =DATE(YEAR(A28),MONTH(A28)+1,DAY(A28)) -> 46327 | B29: 11460.4 | C29: 12725.6 | D29: 15128.84 | E29: 15270.12 | F29: 15252.08 | G29: 13631.36 | H29: 5253.2 | I29: 5508.88 | J29: 5976.52 | K29: 6079.52 | L29: 6199.48 | M29: 5747.68
A30: =DATE(YEAR(A29),MONTH(A29)+1,DAY(A29)) -> 46357 | B30: 10482.16 | C30: 11393.4 | D30: 13305 | E30: 13400.56 | F30: 12925.52 | G30: 11655.24 | H30: 4229.16 | I30: 4498.56 | J30: 4813.96 | K30: 4968.92 | L30: 4897.2 | M30: 4593.52
A31: =DATE(YEAR(A30),MONTH(A30)+1,DAY(A30)) -> 46388 | B31: 11326.2 | C31: 12525.92 | D31: 15561.88 | E31: 16342.44 | F31: 15432.2 | G31: 13054.72 | H31: 4673.52 | I31: 4582.44 | J31: 5087.48 | K31: 5766.76 | L31: 6050.4 | M31: 5575.64
A33: Physical address: | B33: ='48 Part'!B33 -> Walters Road, Kingsland, Auckland
A34: ICP Number: | B34: ='48 Part'!B34 -> 0138572097LCAAE
A35: GXP: | B35: ='48 Part'!B35 -> ROS1101
A36: Commencement: | B36: ='48 Part'!B36 -> 46054
A37: Load Group: | B37: ='48 Part'!B37 -> ATXT | C37: Demand: | D37: ='48 Part'!D37
A38: Loss Factor: | B38: ='48 Part'!B38 -> VECA3 | C38: Capacity: | D38: ='48 Part'!D38 -> 750
A39: Meter owner: | B39: ='48 Part'!B39 -> AMCI | C39: Cat: | D39: ='48 Part'!D39 -> 4
A40: Installation type: | B40: ='48 Part'!B40 -> L
A41: Current supplier: | B41: ='48 Part'!B41 -> Mercury
A42: Est. Usage: | B42: =SUM(B46:M57) -> 1294789.2 | C42: kWh/annum
A44: kWh | B44: Business Day | H44: Non Business Day
B45: 0000-0400 | C45: 0400-0800 | D45: 0800-1200 | E45: 1200-1600 | F45: 1600-2000 | G45: 2000-2400 | H45: 0000-0400 | I45: 0400-0800 | J45: 0800-1200 | K45: 1200-1600 | L45: 1600-2000 | M45: 2000-2400
A46: =B36 -> 46054 | B46: 8026.56 | C46: 9265.6 | D46: 12259.968 | E46: 14362.336 | F46: 12562.208 | G46: 10720.576 | H46: 3370.688 | I46: 3587.104 | J46: 4072.992 | K46: 5244.256 | L46: 5333.6 | M46: 4399.616
A47: =DATE(YEAR(A46),MONTH(A46)+1,DAY(A46)) -> 46082 | B47: 8787.616 | C47: 9700.416 | D47: 13603.2 | E47: 15496.256 | F47: 15085.344 | G47: 12867.84 | H47: 5084.384 | I47: 5098.528 | J47: 5484.544 | K47: 6369.888 | L47: 6655.744 | M47: 5861.216
...
